<?xml version="1.0" encoding="utf-8"?>
<!-- =================================================================================== -->
<!-- |    This document was autogenerated by xacro from /tmp/HEBI_Scara.xacro          | -->
<!-- |    EDITING THIS FILE BY HAND IS NOT RECOMMENDED                                 | -->
<!-- =================================================================================== -->
<robot name="HEBI_Scara" version="1.2.0">
  <!-- This is a single xacro file you can include to get
  all of the HEBI components -->
  <!-- This automatically loads the gazebo plugin for xacro models
       which include hebi.xacro -->
  <gazebo>
    <plugin filename="libhebi_gazebo_plugin.so" name="hebi_gazebo_plugin"/>
  </gazebo>
  <link name="world"/>
  <joint name="world_joint" type="fixed">
    <origin rpy="0 0 0" xyz="0 0 0"/>
    <parent link="world"/>
    <child link="Arm/J1_shoulder/INPUT_INTERFACE"/>
  </joint>
  <link name="Arm/J1_shoulder/INPUT_INTERFACE">
    <visual>
      <origin rpy="0 0 0" xyz="0 0 0"/>
      <geometry>
        <mesh filename="package://hebi_description/meshes/X8.stl" scale="0.001 0.001 0.001"/>
      </geometry>
      <material name="red">
        <color rgba=".82 0.06 0.06 1"/>
      </material>
    </visual>
    <collision>
      <origin rpy="0 0 0" xyz="0 0 0"/>
      <geometry>
        <mesh filename="package://hebi_description/meshes/X8.stl" scale="0.001 0.001 0.001"/>
      </geometry>
    </collision>
    <inertial>
      <mass value="0.48"/>
      <origin rpy="0 0 0" xyz="-0.0145 -0.0031 0.0242"/>
      <inertia ixx="0.000246" ixy="0.0000444" ixz="0.0000266" iyy="0.000380" iyz="0.00000422" izz="0.000463"/>
    </inertial>
  </link>
  <gazebo reference="Arm/J1_shoulder/INPUT_INTERFACE">
    <material>Gazebo/Red</material>
  </gazebo>
  <link name="HEBI_SIM/Arm/J1_shoulder/X8_9">
    <visual>
      <origin rpy="0 0 0" xyz="-0.03 0 0.02"/>
      <geometry>
        <sphere radius="0.001"/>
      </geometry>
    </visual>
    <inertial>
      <mass value="0.001"/>
      <origin rpy="0 0 0" xyz="0 0 0"/>
      <inertia ixx="0.000001" ixy="0" ixz="0" iyy="0.000001" iyz="0" izz="0.000001"/>
    </inertial>
  </link>
  <joint name="HEBI_SIM_JOINT/Arm/J1_shoulder" type="fixed">
    <parent link="Arm/J1_shoulder/INPUT_INTERFACE"/>
    <child link="HEBI_SIM/Arm/J1_shoulder/X8_9"/>
    <origin rpy="0 0 0" xyz="0 0 0"/>
  </joint>
  <gazebo reference="HEBI_SIM_JOINT/Arm/J1_shoulder">
    <disableFixedJointLumping>true</disableFixedJointLumping>
    <preserveFixedJoint>true</preserveFixedJoint>
  </gazebo>
  <joint name="Arm/J1_shoulder" type="continuous">
    <parent link="Arm/J1_shoulder/INPUT_INTERFACE"/>
    <child link="shoulder_elbow/INPUT_INTERFACE"/>
    <origin rpy="0 0 0" xyz="0 0 0.045"/>
    <axis xyz="0 0 1"/>
    <limit effort="20" velocity="30"/>
    <dynamics damping="0.5" friction="0.5"/>
  </joint>
  <link name="shoulder_elbow/INPUT_INTERFACE">
    <!-- Input Cap -->
    <visual>
      <origin rpy="0 0 0" xyz="0 0 0"/>
      <geometry>
        <mesh filename="package://hebi_description/meshes/A-2038-02.stl"/>
      </geometry>
      <material name="black">
        <color rgba="0.1 0.1 0.1 1"/>
      </material>
    </visual>
    <collision>
      <origin rpy="0 0 0" xyz="0 0 0"/>
      <geometry>
        <mesh filename="package://hebi_description/meshes/A-2038-02.stl"/>
      </geometry>
    </collision>
    <!-- Link Pipe -->
    <visual>
      <origin rpy="0 1.57075 0" xyz="0.2625 0 0.02"/>
      <geometry>
        <cylinder length="0.4996" radius=".016"/>
      </geometry>
      <material name="black">
        <color rgba="0.1 0.1 0.1 1"/>
      </material>
    </visual>
    <collision>
      <origin rpy="0 1.57075 0" xyz="0.2625 0 0.02"/>
      <geometry>
        <cylinder length="0.4996" radius=".016"/>
      </geometry>
    </collision>
    <!-- Output Cap -->
    <visual>
      <origin rpy="0 0 0" xyz="0.525 0.0 0.04"/>
      <geometry>
        <mesh filename="package://hebi_description/meshes/A-2039-02.stl"/>
      </geometry>
      <material name="black">
        <color rgba="0.1 0.1 0.1 1"/>
      </material>
    </visual>
    <collision>
      <origin rpy="0 0 0" xyz="0.525 0.0 0.04"/>
      <geometry>
        <mesh filename="package://hebi_description/meshes/A-2039-02.stl"/>
      </geometry>
    </collision>
    <!-- Approximate inertia as thin rod about x axis -->
    <inertial>
      <origin rpy="0 0 0" xyz="0.2625 0 0.02"/>
      <mass value="0.482"/>
      <inertia ixx="0.0" ixy="0.0" ixz="0.0" iyy="0.0110709375" iyz="0.0" izz="0.0110709375"/>
    </inertial>
  </link>
  <gazebo reference="shoulder_elbow/INPUT_INTERFACE">
    <material>Gazebo/Black</material>
  </gazebo>
  <joint name="shoulder_elbow/OUTPUT_JOINT" type="fixed">
    <parent link="shoulder_elbow/INPUT_INTERFACE"/>
    <child link="Arm/J2_elbow/INPUT_INTERFACE"/>
    <origin rpy="0 0 0" xyz="0.525 -0.0 0.04"/>
  </joint>
  <gazebo reference="shoulder_elbow/OUTPUT_JOINT">
    <disableFixedJointLumping>true</disableFixedJointLumping>
    <preserveFixedJoint>true</preserveFixedJoint>
  </gazebo>
  <link name="Arm/J2_elbow/INPUT_INTERFACE">
    <visual>
      <origin rpy="0 0 0" xyz="0 0 0"/>
      <geometry>
        <mesh filename="package://hebi_description/meshes/X8.stl" scale="0.001 0.001 0.001"/>
      </geometry>
      <material name="red">
        <color rgba=".82 0.06 0.06 1"/>
      </material>
    </visual>
    <collision>
      <origin rpy="0 0 0" xyz="0 0 0"/>
      <geometry>
        <mesh filename="package://hebi_description/meshes/X8.stl" scale="0.001 0.001 0.001"/>
      </geometry>
    </collision>
    <inertial>
      <mass value="0.48"/>
      <origin rpy="0 0 0" xyz="-0.0145 -0.0031 0.0242"/>
      <inertia ixx="0.000246" ixy="0.0000444" ixz="0.0000266" iyy="0.000380" iyz="0.00000422" izz="0.000463"/>
    </inertial>
  </link>
  <gazebo reference="Arm/J2_elbow/INPUT_INTERFACE">
    <material>Gazebo/Red</material>
  </gazebo>
  <link name="HEBI_SIM/Arm/J2_elbow/X8_9">
    <visual>
      <origin rpy="0 0 0" xyz="-0.03 0 0.02"/>
      <geometry>
        <sphere radius="0.001"/>
      </geometry>
    </visual>
    <inertial>
      <mass value="0.001"/>
      <origin rpy="0 0 0" xyz="0 0 0"/>
      <inertia ixx="0.000001" ixy="0" ixz="0" iyy="0.000001" iyz="0" izz="0.000001"/>
    </inertial>
  </link>
  <joint name="HEBI_SIM_JOINT/Arm/J2_elbow" type="fixed">
    <parent link="Arm/J2_elbow/INPUT_INTERFACE"/>
    <child link="HEBI_SIM/Arm/J2_elbow/X8_9"/>
    <origin rpy="0 0 0" xyz="0 0 0"/>
  </joint>
  <gazebo reference="HEBI_SIM_JOINT/Arm/J2_elbow">
    <disableFixedJointLumping>true</disableFixedJointLumping>
    <preserveFixedJoint>true</preserveFixedJoint>
  </gazebo>
  <joint name="Arm/J2_elbow" type="continuous">
    <parent link="Arm/J2_elbow/INPUT_INTERFACE"/>
    <child link="elbow_wrist/INPUT_INTERFACE"/>
    <origin rpy="0 0 0" xyz="0 0 0.045"/>
    <axis xyz="0 0 1"/>
    <limit effort="20" velocity="30"/>
    <dynamics damping="0.5" friction="0.5"/>
  </joint>
  <link name="elbow_wrist/INPUT_INTERFACE">
    <!-- Input Cap -->
    <visual>
      <origin rpy="0 0 0" xyz="0 0 0"/>
      <geometry>
        <mesh filename="package://hebi_description/meshes/A-2038-02.stl"/>
      </geometry>
      <material name="black">
        <color rgba="0.1 0.1 0.1 1"/>
      </material>
    </visual>
    <collision>
      <origin rpy="0 0 0" xyz="0 0 0"/>
      <geometry>
        <mesh filename="package://hebi_description/meshes/A-2038-02.stl"/>
      </geometry>
    </collision>
    <!-- Link Pipe -->
    <visual>
      <origin rpy="0 1.57075 0" xyz="0.2625 0 0.02"/>
      <geometry>
        <cylinder length="0.4996" radius=".016"/>
      </geometry>
      <material name="black">
        <color rgba="0.1 0.1 0.1 1"/>
      </material>
    </visual>
    <collision>
      <origin rpy="0 1.57075 0" xyz="0.2625 0 0.02"/>
      <geometry>
        <cylinder length="0.4996" radius=".016"/>
      </geometry>
    </collision>
    <!-- Output Cap -->
    <visual>
      <origin rpy="0 0 0" xyz="0.525 0.0 0.04"/>
      <geometry>
        <mesh filename="package://hebi_description/meshes/A-2039-02.stl"/>
      </geometry>
      <material name="black">
        <color rgba="0.1 0.1 0.1 1"/>
      </material>
    </visual>
    <collision>
      <origin rpy="0 0 0" xyz="0.525 0.0 0.04"/>
      <geometry>
        <mesh filename="package://hebi_description/meshes/A-2039-02.stl"/>
      </geometry>
    </collision>
    <!-- Approximate inertia as thin rod about x axis -->
    <inertial>
      <origin rpy="0 0 0" xyz="0.2625 0 0.02"/>
      <mass value="0.482"/>
      <inertia ixx="0.0" ixy="0.0" ixz="0.0" iyy="0.0110709375" iyz="0.0" izz="0.0110709375"/>
    </inertial>
  </link>
  <gazebo reference="elbow_wrist/INPUT_INTERFACE">
    <material>Gazebo/Black</material>
  </gazebo>
  <joint name="elbow_wrist/OUTPUT_JOINT" type="fixed">
    <parent link="elbow_wrist/INPUT_INTERFACE"/>
    <child link="Arm/J3_wrist/INPUT_INTERFACE"/>
    <origin rpy="0 0 0" xyz="0.525 -0.0 0.04"/>
  </joint>
  <gazebo reference="elbow_wrist/OUTPUT_JOINT">
    <disableFixedJointLumping>true</disableFixedJointLumping>
    <preserveFixedJoint>true</preserveFixedJoint>
  </gazebo>
  <link name="Arm/J3_wrist/INPUT_INTERFACE">
    <visual>
      <origin rpy="0 0 0" xyz="0 0 0"/>
      <geometry>
        <mesh filename="package://hebi_description/meshes/X8.stl" scale="0.001 0.001 0.001"/>
      </geometry>
      <material name="red">
        <color rgba=".82 0.06 0.06 1"/>
      </material>
    </visual>
    <collision>
      <origin rpy="0 0 0" xyz="0 0 0"/>
      <geometry>
        <mesh filename="package://hebi_description/meshes/X8.stl" scale="0.001 0.001 0.001"/>
      </geometry>
    </collision>
    <inertial>
      <mass value="0.48"/>
      <origin rpy="0 0 0" xyz="-0.0145 -0.0031 0.0242"/>
      <inertia ixx="0.000246" ixy="0.0000444" ixz="0.0000266" iyy="0.000380" iyz="0.00000422" izz="0.000463"/>
    </inertial>
  </link>
  <gazebo reference="Arm/J3_wrist/INPUT_INTERFACE">
    <material>Gazebo/Red</material>
  </gazebo>
  <link name="HEBI_SIM/Arm/J3_wrist/X8_9">
    <visual>
      <origin rpy="0 0 0" xyz="-0.03 0 0.02"/>
      <geometry>
        <sphere radius="0.001"/>
      </geometry>
    </visual>
    <inertial>
      <mass value="0.001"/>
      <origin rpy="0 0 0" xyz="0 0 0"/>
      <inertia ixx="0.000001" ixy="0" ixz="0" iyy="0.000001" iyz="0" izz="0.000001"/>
    </inertial>
  </link>
  <joint name="HEBI_SIM_JOINT/Arm/J3_wrist" type="fixed">
    <parent link="Arm/J3_wrist/INPUT_INTERFACE"/>
    <child link="HEBI_SIM/Arm/J3_wrist/X8_9"/>
    <origin rpy="0 0 0" xyz="0 0 0"/>
  </joint>
  <gazebo reference="HEBI_SIM_JOINT/Arm/J3_wrist">
    <disableFixedJointLumping>true</disableFixedJointLumping>
    <preserveFixedJoint>true</preserveFixedJoint>
  </gazebo>
  <joint name="Arm/J3_wrist" type="continuous">
    <parent link="Arm/J3_wrist/INPUT_INTERFACE"/>
    <child link="end_effector/INPUT_INTERFACE"/>
    <origin rpy="0 0 0" xyz="0 0 0.045"/>
    <axis xyz="0 0 1"/>
    <limit effort="20" velocity="30"/>
    <dynamics damping="0.5" friction="0.5"/>
  </joint>
  <link name="end_effector/INPUT_INTERFACE">
    <visual>
      <origin rpy="0 0 0" xyz="0 0 0.0005"/>
      <geometry>
        <box rpy="0 0 0" size="0.001 0.001 0.001"/>
      </geometry>
    </visual>
    <inertial>
      <origin rpy="0 0 0" xyz="0 0 0"/>
      <mass value="0.2"/>
      <inertia ixx="0.0008" ixy="0.0" ixz="0.0" iyy="0.0008" iyz="0.0" izz="0.0008"/>
    </inertial>
  </link>
</robot>

