<sdf version='1.6'>
  <model name='HEBI_Scara'>
    <link name='HEBI/J1_shoulder/INPUT_INTERFACE'>
      <pose frame=''>0 0 0 0 -0 0</pose>
      <inertial>
        <pose frame=''>-0.0145 -0.0031 0.0242 0 -0 0</pose>
        <mass>0.48</mass>
        <inertia>
          <ixx>0.000246</ixx>
          <ixy>4.44e-05</ixy>
          <ixz>2.66e-05</ixz>
          <iyy>0.00038</iyy>
          <iyz>4.22e-06</iyz>
          <izz>0.000463</izz>
        </inertia>
      </inertial>
      <collision name='HEBI/J1_shoulder/INPUT_INTERFACE_collision'>
        <pose frame=''>0 0 0 0 -0 0</pose>
        <geometry>
          <mesh>
            <scale>0.001 0.001 0.001</scale>
            <uri>model://hebi_description/meshes/X8.stl</uri>
          </mesh>
        </geometry>
        <surface>
          <contact>
            <ode/>
          </contact>
          <friction>
            <ode/>
          </friction>
        </surface>
      </collision>
      <visual name='HEBI/J1_shoulder/INPUT_INTERFACE_visual'>
        <pose frame=''>0 0 0 0 -0 0</pose>
        <geometry>
          <mesh>
            <scale>0.001 0.001 0.001</scale>
            <uri>model://hebi_description/meshes/X8.stl</uri>
          </mesh>
        </geometry>
        <material>
          <script>
            <name>Gazebo/Red</name>
            <uri>file://media/materials/scripts/gazebo.material</uri>
          </script>
        </material>
      </visual>
      <gravity>1</gravity>
      <velocity_decay/>
    </link>
    <joint name='world_joint' type='fixed'>
      <child>HEBI/J1_shoulder/INPUT_INTERFACE</child>
      <parent>world</parent>
    </joint>
    <link name='shoulder_elbow/INPUT_INTERFACE'>
      <pose frame=''>0 0 0.045 0 -0 0</pose>
      <inertial>
        <pose frame=''>0.2625 0 0.02 0 -0 0</pose>
        <mass>0.482</mass>
        <inertia>
          <ixx>0</ixx>
          <ixy>0</ixy>
          <ixz>0</ixz>
          <iyy>0.0110709</iyy>
          <iyz>0</iyz>
          <izz>0.0110709</izz>
        </inertia>
      </inertial>
      <collision name='shoulder_elbow/INPUT_INTERFACE_collision'>
        <pose frame=''>0 0 0 0 -0 0</pose>
        <geometry>
          <mesh>
            <scale>1 1 1</scale>
            <uri>model://hebi_description/meshes/A-2038-02.stl</uri>
          </mesh>
        </geometry>
        <surface>
          <contact>
            <ode/>
          </contact>
          <friction>
            <ode/>
          </friction>
        </surface>
      </collision>
      <collision name='shoulder_elbow/INPUT_INTERFACE_collision_1'>
        <pose frame=''>0.2625 0 0.02 3.14159 1.57079 3.14159</pose>
        <geometry>
          <cylinder>
            <length>0.4996</length>
            <radius>0.016</radius>
          </cylinder>
        </geometry>
        <surface>
          <contact>
            <ode/>
          </contact>
          <friction>
            <ode/>
          </friction>
        </surface>
      </collision>
      <collision name='shoulder_elbow/INPUT_INTERFACE_collision_2'>
        <pose frame=''>0.525 0 0.04 0 -0 0</pose>
        <geometry>
          <mesh>
            <scale>1 1 1</scale>
            <uri>model://hebi_description/meshes/A-2039-02.stl</uri>
          </mesh>
        </geometry>
        <surface>
          <contact>
            <ode/>
          </contact>
          <friction>
            <ode/>
          </friction>
        </surface>
      </collision>
      <visual name='shoulder_elbow/INPUT_INTERFACE_visual'>
        <pose frame=''>0 0 0 0 -0 0</pose>
        <geometry>
          <mesh>
            <scale>1 1 1</scale>
            <uri>model://hebi_description/meshes/A-2038-02.stl</uri>
          </mesh>
        </geometry>
        <material>
          <script>
            <name>Gazebo/Black</name>
            <uri>file://media/materials/scripts/gazebo.material</uri>
          </script>
        </material>
      </visual>
      <visual name='shoulder_elbow/INPUT_INTERFACE_visual_1'>
        <pose frame=''>0.2625 0 0.02 3.14159 1.57079 3.14159</pose>
        <geometry>
          <cylinder>
            <length>0.4996</length>
            <radius>0.016</radius>
          </cylinder>
        </geometry>
        <material>
          <script>
            <name>Gazebo/Black</name>
            <uri>file://media/materials/scripts/gazebo.material</uri>
          </script>
        </material>
      </visual>
      <visual name='shoulder_elbow/INPUT_INTERFACE_visual_2'>
        <pose frame=''>0.525 0 0.04 0 -0 0</pose>
        <geometry>
          <mesh>
            <scale>1 1 1</scale>
            <uri>model://hebi_description/meshes/A-2039-02.stl</uri>
          </mesh>
        </geometry>
        <material>
          <script>
            <name>Gazebo/Black</name>
            <uri>file://media/materials/scripts/gazebo.material</uri>
          </script>
        </material>
      </visual>
      <gravity>1</gravity>
      <velocity_decay/>
    </link>
    <joint name='HEBI/J1_shoulder/X8_9' type='revolute'>
      <child>shoulder_elbow/INPUT_INTERFACE</child>
      <parent>HEBI/J1_shoulder/INPUT_INTERFACE</parent>
      <axis>
        <xyz>0 0 1</xyz>
        <limit>
          <lower>-1e+16</lower>
          <upper>1e+16</upper>
        </limit>
        <dynamics>
          <damping>0.5</damping>
          <friction>0.5</friction>
          <spring_reference>0</spring_reference>
          <spring_stiffness>0</spring_stiffness>
        </dynamics>
        <use_parent_model_frame>1</use_parent_model_frame>
      </axis>
    </joint>
    <link name='HEBI/J2_elbow/INPUT_INTERFACE'>
      <pose frame=''>0.525 0 0.085 0 -0 0</pose>
      <inertial>
        <pose frame=''>-0.0145 -0.0031 0.0242 0 -0 0</pose>
        <mass>0.48</mass>
        <inertia>
          <ixx>0.000246</ixx>
          <ixy>4.44e-05</ixy>
          <ixz>2.66e-05</ixz>
          <iyy>0.00038</iyy>
          <iyz>4.22e-06</iyz>
          <izz>0.000463</izz>
        </inertia>
      </inertial>
      <collision name='HEBI/J2_elbow/INPUT_INTERFACE_collision'>
        <pose frame=''>0 0 0 0 -0 0</pose>
        <geometry>
          <mesh>
            <scale>0.001 0.001 0.001</scale>
            <uri>model://hebi_description/meshes/X8.stl</uri>
          </mesh>
        </geometry>
        <surface>
          <contact>
            <ode/>
          </contact>
          <friction>
            <ode/>
          </friction>
        </surface>
      </collision>
      <visual name='HEBI/J2_elbow/INPUT_INTERFACE_visual'>
        <pose frame=''>0 0 0 0 -0 0</pose>
        <geometry>
          <mesh>
            <scale>0.001 0.001 0.001</scale>
            <uri>model://hebi_description/meshes/X8.stl</uri>
          </mesh>
        </geometry>
        <material>
          <script>
            <name>Gazebo/Red</name>
            <uri>file://media/materials/scripts/gazebo.material</uri>
          </script>
        </material>
      </visual>
      <gravity>1</gravity>
      <velocity_decay/>
    </link>
    <joint name='shoulder_elbow/OUTPUT_JOINT' type='fixed'>
      <child>HEBI/J2_elbow/INPUT_INTERFACE</child>
      <parent>shoulder_elbow/INPUT_INTERFACE</parent>
      <axis>
        <dynamics>
          <spring_reference>0</spring_reference>
          <spring_stiffness>0</spring_stiffness>
        </dynamics>
        <use_parent_model_frame>1</use_parent_model_frame>
        <xyz>0 0 1</xyz>
        <limit>
          <lower>-1e+16</lower>
          <upper>1e+16</upper>
        </limit>
      </axis>
      <physics>
        <ode>
          <limit>
            <cfm>0</cfm>
            <erp>0.2</erp>
          </limit>
        </ode>
      </physics>
    </joint>
    <link name='elbow_wrist/INPUT_INTERFACE'>
      <pose frame=''>0.525 0 0.13 0 -0 0</pose>
      <inertial>
        <pose frame=''>0.2625 0 0.02 0 -0 0</pose>
        <mass>0.482</mass>
        <inertia>
          <ixx>0</ixx>
          <ixy>0</ixy>
          <ixz>0</ixz>
          <iyy>0.0110709</iyy>
          <iyz>0</iyz>
          <izz>0.0110709</izz>
        </inertia>
      </inertial>
      <collision name='elbow_wrist/INPUT_INTERFACE_collision'>
        <pose frame=''>0 0 0 0 -0 0</pose>
        <geometry>
          <mesh>
            <scale>1 1 1</scale>
            <uri>model://hebi_description/meshes/A-2038-02.stl</uri>
          </mesh>
        </geometry>
        <surface>
          <contact>
            <ode/>
          </contact>
          <friction>
            <ode/>
          </friction>
        </surface>
      </collision>
      <collision name='elbow_wrist/INPUT_INTERFACE_collision_1'>
        <pose frame=''>0.2625 0 0.02 3.14159 1.57079 3.14159</pose>
        <geometry>
          <cylinder>
            <length>0.4996</length>
            <radius>0.016</radius>
          </cylinder>
        </geometry>
        <surface>
          <contact>
            <ode/>
          </contact>
          <friction>
            <ode/>
          </friction>
        </surface>
      </collision>
      <collision name='elbow_wrist/INPUT_INTERFACE_collision_2'>
        <pose frame=''>0.525 0 0.04 0 -0 0</pose>
        <geometry>
          <mesh>
            <scale>1 1 1</scale>
            <uri>model://hebi_description/meshes/A-2039-02.stl</uri>
          </mesh>
        </geometry>
        <surface>
          <contact>
            <ode/>
          </contact>
          <friction>
            <ode/>
          </friction>
        </surface>
      </collision>
      <visual name='elbow_wrist/INPUT_INTERFACE_visual'>
        <pose frame=''>0 0 0 0 -0 0</pose>
        <geometry>
          <mesh>
            <scale>1 1 1</scale>
            <uri>model://hebi_description/meshes/A-2038-02.stl</uri>
          </mesh>
        </geometry>
        <material>
          <script>
            <name>Gazebo/Black</name>
            <uri>file://media/materials/scripts/gazebo.material</uri>
          </script>
        </material>
      </visual>
      <visual name='elbow_wrist/INPUT_INTERFACE_visual_1'>
        <pose frame=''>0.2625 0 0.02 3.14159 1.57079 3.14159</pose>
        <geometry>
          <cylinder>
            <length>0.4996</length>
            <radius>0.016</radius>
          </cylinder>
        </geometry>
        <material>
          <script>
            <name>Gazebo/Black</name>
            <uri>file://media/materials/scripts/gazebo.material</uri>
          </script>
        </material>
      </visual>
      <visual name='elbow_wrist/INPUT_INTERFACE_visual_2'>
        <pose frame=''>0.525 0 0.04 0 -0 0</pose>
        <geometry>
          <mesh>
            <scale>1 1 1</scale>
            <uri>model://hebi_description/meshes/A-2039-02.stl</uri>
          </mesh>
        </geometry>
        <material>
          <script>
            <name>Gazebo/Black</name>
            <uri>file://media/materials/scripts/gazebo.material</uri>
          </script>
        </material>
      </visual>
      <gravity>1</gravity>
      <velocity_decay/>
    </link>
    <joint name='HEBI/J2_elbow/X8_9' type='revolute'>
      <child>elbow_wrist/INPUT_INTERFACE</child>
      <parent>HEBI/J2_elbow/INPUT_INTERFACE</parent>
      <axis>
        <xyz>0 0 1</xyz>
        <limit>
          <lower>-1e+16</lower>
          <upper>1e+16</upper>
        </limit>
        <dynamics>
          <damping>0.5</damping>
          <friction>0.5</friction>
          <spring_reference>0</spring_reference>
          <spring_stiffness>0</spring_stiffness>
        </dynamics>
        <use_parent_model_frame>1</use_parent_model_frame>
      </axis>
    </joint>
    <link name='HEBI/J3_wrist/INPUT_INTERFACE'>
      <pose frame=''>1.05 0 0.17 0 -0 0</pose>
      <inertial>
        <pose frame=''>-0.0145 -0.0031 0.0242 0 -0 0</pose>
        <mass>0.48</mass>
        <inertia>
          <ixx>0.000246</ixx>
          <ixy>4.44e-05</ixy>
          <ixz>2.66e-05</ixz>
          <iyy>0.00038</iyy>
          <iyz>4.22e-06</iyz>
          <izz>0.000463</izz>
        </inertia>
      </inertial>
      <collision name='HEBI/J3_wrist/INPUT_INTERFACE_collision'>
        <pose frame=''>0 0 0 0 -0 0</pose>
        <geometry>
          <mesh>
            <scale>0.001 0.001 0.001</scale>
            <uri>model://hebi_description/meshes/X8.stl</uri>
          </mesh>
        </geometry>
        <surface>
          <contact>
            <ode/>
          </contact>
          <friction>
            <ode/>
          </friction>
        </surface>
      </collision>
      <visual name='HEBI/J3_wrist/INPUT_INTERFACE_visual'>
        <pose frame=''>0 0 0 0 -0 0</pose>
        <geometry>
          <mesh>
            <scale>0.001 0.001 0.001</scale>
            <uri>model://hebi_description/meshes/X8.stl</uri>
          </mesh>
        </geometry>
        <material>
          <script>
            <name>Gazebo/Red</name>
            <uri>file://media/materials/scripts/gazebo.material</uri>
          </script>
        </material>
      </visual>
      <gravity>1</gravity>
      <velocity_decay/>
    </link>
    <joint name='elbow_wrist/OUTPUT_JOINT' type='fixed'>
      <child>HEBI/J3_wrist/INPUT_INTERFACE</child>
      <parent>elbow_wrist/INPUT_INTERFACE</parent>
      <axis>
        <dynamics>
          <spring_reference>0</spring_reference>
          <spring_stiffness>0</spring_stiffness>
        </dynamics>
        <use_parent_model_frame>1</use_parent_model_frame>
        <xyz>0 0 1</xyz>
        <limit>
          <lower>-1e+16</lower>
          <upper>1e+16</upper>
        </limit>
      </axis>
      <physics>
        <ode>
          <limit>
            <cfm>0</cfm>
            <erp>0.2</erp>
          </limit>
        </ode>
      </physics>
    </joint>
    <link name='end_effector/INPUT_INTERFACE'>
      <pose frame=''>1.05 0 0.215 0 -0 0</pose>
      <inertial>
        <pose frame=''>0 0 0 0 -0 0</pose>
        <mass>0.02</mass>
        <inertia>
          <ixx>8e-05</ixx>
          <ixy>0</ixy>
          <ixz>0</ixz>
          <iyy>8e-05</iyy>
          <iyz>0</iyz>
          <izz>8e-05</izz>
        </inertia>
      </inertial>
      <collision name='end_effector/INPUT_INTERFACE_collision'>
        <pose frame=''>0 0 0.0005 0 -0 0</pose>
        <geometry>
          <box>
            <size>0.001 0.001 0.001</size>
          </box>
        </geometry>
      </collision>
      <visual name='end_effector/INPUT_INTERFACE_visual'>
        <pose frame=''>0 0 0.0005 0 -0 0</pose>
        <geometry>
          <box>
            <size>0.001 0.001 0.001</size>
          </box>
        </geometry>
      </visual>
    </link>
    <joint name='HEBI/J3_wrist/X8_9' type='revolute'>
      <child>end_effector/INPUT_INTERFACE</child>
      <parent>HEBI/J3_wrist/INPUT_INTERFACE</parent>
      <axis>
        <xyz>0 0 1</xyz>
        <limit>
          <lower>-1e+16</lower>
          <upper>1e+16</upper>
        </limit>
        <dynamics>
          <damping>0.5</damping>
          <friction>0.5</friction>
          <spring_reference>0</spring_reference>
          <spring_stiffness>0</spring_stiffness>
        </dynamics>
        <use_parent_model_frame>1</use_parent_model_frame>
      </axis>
    </joint>
    <static>0</static>
    <plugin name='hebi_gazebo_plugin' filename='libhebi_gazebo_plugin.so'/>
  </model>
</sdf>
